<?xml version="1.0"?>
<robot xmlns:xacro="http://www.ros.org/wiki/xacro" name="jaw_gripper">
  <!-- Links Mass -->
  <xacro:property name="gripper_base_mass" value="0.923" />
  <xacro:property name="outer_mass" value="0.091" />
  <xacro:property name="inner_mass" value="0.194" />
  <xacro:property name="finger_mass" value="0.174" />
  <!-- Links COG -->
  <xacro:property name="gripper_base_cog" value="0 26.28e-3 0" />
  <xacro:property name="outer_cog" value="0 31.725e-3 0" />
  <xacro:property name="r_inner_cog" value="-0.316e-3 23.873e-3 0" />
  <xacro:property name="l_inner_cog" value="0.316e-3 23.873e-3 0" />
  <xacro:property name="r_finger_cog" value="3.441e-3 20.353e-3 0" />
  <xacro:property name="l_finger_cog" value="-3.441e-3 20.353e-3 0" />  
  <!-- Dampings -->
  <xacro:property name="inner_damping" value="0" />
  <xacro:property name="outer_damping" value="0" />
  <xacro:property name="finger_damping" value="0" />
  <!-- Visual Meshes -->
  <xacro:property name="gripper_base_mesh_v" value="package://kraft_description/meshes/visual/gripper_base.dae" /> 
  <xacro:property name="outer_mesh_v" value="package://kraft_description/meshes/visual/outer_pivot.dae" />
  <xacro:property name="r_inner_mesh_v" value="package://kraft_description/meshes/visual/r_inner_pivot.dae" />
  <xacro:property name="l_inner_mesh_v" value="package://kraft_description/meshes/visual/l_inner_pivot.dae" /> 
  <xacro:property name="r_finger_mesh_v" value="package://kraft_description/meshes/visual/r_finger.dae" />
  <xacro:property name="l_finger_mesh_v" value="package://kraft_description/meshes/visual/l_finger.dae" />
  <!-- Collision Meshes -->
  <xacro:property name="gripper_base_mesh_c" value="package://kraft_description/meshes/collision/gripper_base.dae" /> 
  <xacro:property name="outer_mesh_c" value="package://kraft_description/meshes/collision/outer_pivot.dae" />
  <xacro:property name="r_inner_mesh_c" value="package://kraft_description/meshes/collision/r_inner_pivot.dae" />
  <xacro:property name="l_inner_mesh_c" value="package://kraft_description/meshes/collision/l_inner_pivot.dae" /> 
  <xacro:property name="r_finger_mesh_c" value="package://kraft_description/meshes/collision/r_finger.dae" />
  <xacro:property name="l_finger_mesh_c" value="package://kraft_description/meshes/collision/l_finger.dae" />
  
  <!-- Links Inertia -->
  <xacro:macro name="gripper_base_inertia">
    <inertial>
        <mass value="${gripper_base_mass}"/>
        <origin xyz="${gripper_base_cog}" rpy="0 0 0"/>
        <inertia ixx="9.67e-4" ixy="0.0" ixz="0.0" iyy="0.002" iyz="0.0"
          izz="0.002" />
    </inertial>
  </xacro:macro>

  <xacro:macro name="outer_inertia">
    <inertial>
        <mass value="${outer_mass}"/>
        <origin xyz="${outer_cog}" rpy="0 0 0"/>
        <inertia ixx="4.664e-5" ixy="0.0" ixz="0.0" iyy="5.519e-6"
          iyz="0.0" izz="4.682e-5" />
    </inertial>
  </xacro:macro>

  <xacro:macro name="r_inner_inertia">
    <inertial>
        <mass value="${inner_mass}"/>
        <origin xyz="${r_inner_cog}" rpy="0 0 0"/>
        <inertia ixx="1.179e-4" ixy="1.347e-6" ixz="0.0" iyy="5.647e-5"
          iyz="0.0" izz="7.353e-5" />
    </inertial>
  </xacro:macro>

  <xacro:macro name="l_inner_inertia">
    <inertial>
        <mass value="${inner_mass}"/>
        <origin xyz="${l_inner_cog}" rpy="0 0 0"/>
        <inertia ixx="1.179e-4" ixy="-1.347e-6" ixz="0.0" iyy="5.647e-5"
          iyz="0.0" izz="7.353e-5" />
    </inertial>
  </xacro:macro>

  <xacro:macro name="r_finger_inertia">
    <inertial>
        <mass value="${finger_mass}"/>
        <origin xyz="${r_finger_cog}" rpy="0 0 0"/>
        <inertia ixx="1.65e-4" ixy="3.16e-5" ixz="0.0" iyy="3.595e-5"
          iyz="0.0" izz="1.701e-4" />
    </inertial>
  </xacro:macro>

  <xacro:macro name="l_finger_inertia">
    <inertial>
        <mass value="${finger_mass}"/>
        <origin xyz="${l_finger_cog}" rpy="0 0 0"/>
        <inertia ixx="1.65e-4" ixy="-3.16e-5" ixz="0.0" iyy="3.595e-5"
          iyz="0.0" izz="1.701e-4" />
    </inertial>
  </xacro:macro>
  
  <!-- Links Collision -->
  <xacro:macro name="finger_collision" params="mesh">
    <collision name="collision">
      <geometry>
        <!--<cylinder radius="0.1" length="0.2" />-->
        <mesh filename="${mesh}" />
      </geometry>
    </collision>
  </xacro:macro>

  <xacro:macro name="simple_gripper" params="parent">
    <!-- base link -->
    <create_link name="gripper_base" color="metal_seamed" mesh="${gripper_base_mesh_v}">
    <gripper_base_inertia />
      <finger_collision mesh="${gripper_base_mesh_c}"/>
    </create_link>

    <!-- outer links -->
    <create_link name="r_outer" color="metal_seamed" mesh="${outer_mesh_v}">
      <outer_inertia />
      <finger_collision mesh="${outer_mesh_c}"/>
    </create_link>
    <create_link name="l_outer" color="metal_seamed" mesh="${outer_mesh_v}">
      <outer_inertia />
      <finger_collision mesh="${outer_mesh_c}"/>
    </create_link>

    <!-- inner links -->
    <create_link name="r_inner" color="metal_seamed" mesh="${r_inner_mesh_v}">
      <r_inner_inertia />
      <finger_collision mesh="${r_inner_mesh_c}"/>
    </create_link>
    <create_link name="l_inner" color="metal_seamed" mesh="${l_inner_mesh_v}">
      <l_inner_inertia />
      <finger_collision mesh="${l_inner_mesh_c}"/>
    </create_link>

    <!-- finger links -->
    <create_link name="r_finger" color="metal_seamed" mesh="${r_finger_mesh_v}">
      <r_finger_inertia />
      <finger_collision mesh="${r_finger_mesh_c}"/>
    </create_link>
    <create_link name="l_finger" color="metal_seamed" mesh="${l_finger_mesh_v}">
      <l_finger_inertia />
      <finger_collision mesh="${l_finger_mesh_c}"/>
    </create_link>

    <!-- joints -->
    <joint name="gripper_base_joint" type="fixed">
      <parent link="${parent}" />
      <child link="gripper_base" />
      <origin rpy="0 0 0" xyz="0 0 0"/>
    </joint>

    <joint name="r_inner" type="revolute">
      <child link="r_inner" />
      <parent link="gripper_base" />
      <axis xyz="0 0 1" />
      <origin xyz="31.737e-3 42.19e-3 0" rpy="0 0 0" />
      <limit lower="-1.43" upper="0.4" effort="${gripper_effort}" velocity="${gripper_velocity}" />
      <dynamics damping="${inner_damping}" />
    </joint>
    <joint name="l_inner" type="revolute">
      <child link="l_inner" />
      <parent link="gripper_base" />
      <axis xyz="0 0 1" />
      <origin xyz="-31.737e-3 42.19e-3 0" rpy="0 0 0" />
      <limit lower="-0.4" upper="1.43" effort="${gripper_effort}" velocity="${gripper_velocity}" />
      <dynamics damping="${inner_damping}" />
    </joint>
    
    <joint name="r_outer" type="revolute">
      <child link="r_outer" />
      <parent link="gripper_base" />
      <axis xyz="0 0 1" />
      <origin xyz="58.93e-3 26.49e-3 0" rpy="0 0 0" />
      <limit lower="-1.43" upper="0.4" effort="${gripper_effort}" velocity="${gripper_velocity}" />
      <dynamics damping="${outer_damping}" />
    </joint>
    <joint name="l_outer" type="revolute">
      <child link="l_outer" />
      <parent link="gripper_base" />
      <axis xyz="0 0 1" />
      <origin xyz="-58.93e-3 26.49e-3 0" rpy="0 0 0" />
      <limit lower="-0.4" upper="1.43" effort="${gripper_effort}" velocity="${gripper_velocity}" />
      <dynamics damping="${outer_damping}" />
    </joint>

    <joint name="r_finger" type="revolute">
      <child link="r_finger" />
      <parent link="r_inner" />
      <axis xyz="0 0 1" />
      <origin xyz="0 63.45e-3 0" rpy="0 0 0" />
      <limit lower="${-pi/2}" upper="${pi/2}" effort="${gripper_effort}" velocity="${gripper_velocity}" />
      <dynamics damping="${finger_damping}" />
    </joint>
    <joint name="l_finger" type="revolute">
      <child link="l_finger" />
      <parent link="l_inner" />
      <axis xyz="0 0 1" />
      <origin xyz="0 63.45e-3 0" rpy="0 0 0" />
      <limit lower="${-pi/2}" upper="${pi/2}" effort="${gripper_effort}" velocity="${gripper_velocity}" />
      <dynamics damping="${finger_damping}" />
    </joint>

    <!-- transmissions -->
    <simple_transmission joint="r_outer" />
    <simple_transmission joint="l_outer" />
    <simple_transmission joint="r_inner" />
    <simple_transmission joint="l_inner" />
    <simple_transmission joint="r_finger" />
    <simple_transmission joint="l_finger" />
    
    <!-- links -->
    <gazebo reference="gripper_base">
      <material>Telerobcar/MetalSeamed</material>
      <selfCollide>false</selfCollide>
    </gazebo>
    <gazebo reference="r_outer">
      <material>Telerobcar/MetalSeamed</material>
      <selfCollide>false</selfCollide>
    </gazebo>
    <gazebo reference="l_outer">
      <material>Telerobcar/MetalSeamed</material>
      <selfCollide>false</selfCollide>
    </gazebo>
    <gazebo reference="r_inner">
      <material>Telerobcar/MetalSeamed</material>
      <selfCollide>false</selfCollide>
    </gazebo>
    <gazebo reference="l_inner">
      <material>Telerobcar/MetalSeamed</material>
      <selfCollide>false</selfCollide>
    </gazebo>
    <gazebo reference="r_finger">
      <material>Telerobcar/MetalSeamed</material>
      <selfCollide>false</selfCollide>
      <mu1>1.1</mu1>
      <mu2>1.1</mu2>
      <fdir1>0 0 1</fdir1>
      <kp>1000000.0</kp>
      <kd>10.0</kd>
      <maxVel>0.1</maxVel>
      <minDepth>0.001</minDepth>
      <maxContacts>5</maxContacts>
    </gazebo>
    <gazebo reference="l_finger">
      <material>Telerobcar/MetalSeamed</material>
      <selfCollide>false</selfCollide>
      <mu1>1.1</mu1>
      <mu2>1.1</mu2>
      <fdir1>0 0 1</fdir1>
      <kp>1000000.0</kp>
      <kd>100.0</kd>
      <maxVel>0.1</maxVel>
      <minDepth>0.001</minDepth>
      <maxContacts>5</maxContacts>
    </gazebo>	
    <gazebo>
      <gripper name="grasping">
        <grasp_check>
          <attach_steps>1</attach_steps>    <!-- default: 20 -->
          <detach_steps>1</detach_steps>    <!-- default: 40 -->
          <min_contact_count>2</min_contact_count>
        </grasp_check>
        <gripper_link>r_finger</gripper_link>
        <gripper_link>l_finger</gripper_link>
        <palm_link>gripper_base</palm_link>
      </gripper>
    </gazebo>
  </xacro:macro>
</robot>
