<?xml version="1.0" ?>
<!-- =================================================================================== -->
<!-- |    This document was autogenerated by xacro from kraft.xacro                    | -->
<!-- |    EDITING THIS FILE BY HAND IS NOT RECOMMENDED                                 | -->
<!-- =================================================================================== -->
<robot name="kraft" xmlns:xacro="http://www.ros.org/wiki/xacro">
  <material name="black">
    <color rgba="0.0 0.0 0.0 1.0"/>
  </material>
  <material name="blue">
    <color rgba="0.0 0.0 0.8 1.0"/>
  </material>
  <material name="green">
    <color rgba="0.0 0.8 0.0 1.0"/>
  </material>
  <material name="grey">
    <color rgba="0.2 0.2 0.2 1.0"/>
  </material>
  <material name="orange">
    <color rgba="1.0 0.423529411765 0.0392156862745 1.0"/>
  </material>
  <material name="brown">
    <color rgba="0.870588235294 0.811764705882 0.764705882353 1.0"/>
  </material>
  <material name="red">
    <color rgba="0.8 0.0 0.0 1.0"/>
  </material>
  <material name="white">
    <color rgba="1.0 1.0 1.0 1.0"/>
  </material>
  <material name="metal_seamed">
    <color rgba="0.4627450980392157 0.4666666666666667 0.4509803921568628 1.0"/>
  </material>
  <!-- Create the grips robot -->
  <link name="world"/>
  <link name="base_link">
    <visual>
      <geometry>
        <mesh filename="package://kraft_description/meshes/visual/base.dae"/>
      </geometry>
      <material name="black"/>
    </visual>
    <collision>
      <origin rpy="0 0 0" xyz="0 0 0.00762"/>
      <geometry>
        <cylinder length="0.01524" radius="0.125"/>
      </geometry>
    </collision>
    <inertial>
      <origin rpy="0 0 0" xyz="0 0 0.00762"/>
      <mass value="1.208"/>
      <inertia ixx="0.0047421305984" ixy="0.0" ixz="0.0" iyy="0.0047421305984" iyz="0.0" izz="0.0094375"/>
    </inertial>
  </link>
  <link name="manifold">
    <visual>
      <geometry>
        <mesh filename="package://kraft_description/meshes/visual/manifold.dae"/>
      </geometry>
      <material name="black"/>
    </visual>
    <collision>
      <origin rpy="0 0 0" xyz="0 0 0.16906"/>
      <geometry>
        <cylinder length="0.33812" radius="0.205"/>
      </geometry>
    </collision>
    <inertial>
      <origin rpy="0 0 0" xyz="0 0 0.16906"/>
      <mass value="41.111"/>
      <inertia ixx="0.82359082711" ixy="0.0" ixz="0.0" iyy="0.82359082711" iyz="0.0" izz="0.8638448875"/>
    </inertial>
  </link>
  <link name="upper_arm">
    <visual>
      <geometry>
        <mesh filename="package://kraft_description/meshes/visual/upper_arm.dae"/>
      </geometry>
      <material name="black"/>
    </visual>
    <collision>
      <origin rpy="0 0 0" xyz="0 0 0.260835"/>
      <geometry>
        <cylinder length="0.52167" radius="0.075"/>
      </geometry>
    </collision>
    <inertial>
      <origin rpy="0 0 0" xyz="0 0 0.260835"/>
      <mass value="3.592"/>
      <inertia ixx="0.0865117002774" ixy="0.0" ixz="0.0" iyy="0.0865117002774" iyz="0.0" izz="0.0101025"/>
    </inertial>
  </link>
  <link name="forearm">
    <visual>
      <geometry>
        <mesh filename="package://kraft_description/meshes/visual/forearm.dae"/>
      </geometry>
      <material name="black"/>
    </visual>
    <collision>
      <origin rpy="1.57079632679 0 0" xyz="0 0.069139 0"/>
      <geometry>
        <cylinder length="0.385078" radius="0.075"/>
      </geometry>
    </collision>
    <inertial>
      <origin rpy="0 0 0" xyz="0 0.069139 0"/>
      <mass value="4.935"/>
      <inertia ixx="0.067922077177" ixy="0.0" ixz="0.0" iyy="0.0138796875" iyz="0.0" izz="0.067922077177"/>
    </inertial>
  </link>
  <link name="pitch">
    <visual>
      <geometry>
        <mesh filename="package://kraft_description/meshes/visual/pitch.dae"/>
      </geometry>
      <material name="black"/>
    </visual>
    <collision>
      <origin rpy="1.57079632679 0 0" xyz="0 0.0666115 0"/>
      <geometry>
        <cylinder length="0.133223" radius="0.075"/>
      </geometry>
    </collision>
    <inertial>
      <origin rpy="0 0 0" xyz="0 0.0666115 0"/>
      <mass value="0.679"/>
      <inertia ixx="0.00195910555733" ixy="0.0" ixz="0.0" iyy="0.0019096875" iyz="0.0" izz="0.00195910555733"/>
    </inertial>
  </link>
  <link name="yaw">
    <visual>
      <geometry>
        <mesh filename="package://kraft_description/meshes/visual/yaw.dae"/>
      </geometry>
      <material name="black"/>
    </visual>
    <collision>
      <origin rpy="1.57079632679 0 0" xyz="0 0.095446 0"/>
      <geometry>
        <cylinder length="0.190892" radius="0.085"/>
      </geometry>
    </collision>
    <inertial>
      <origin rpy="0 0 0" xyz="0 0.095446 0"/>
      <mass value="4.689"/>
      <inertia ixx="0.0227083407757" ixy="0.0" ixz="0.0" iyy="0.0169390125" iyz="0.0" izz="0.0227083407757"/>
    </inertial>
  </link>
  <link name="end_effector">
    <visual>
      <geometry>
        <sphere radius="0.01"/>
      </geometry>
      <material name="blue"/>
    </visual>
    <collision>
      <geometry>
        <sphere radius="0.01"/>
      </geometry>
    </collision>
    <inertial>
      <origin rpy="0 0 0" xyz="0 0 0.01"/>
      <mass value="0.05"/>
      <inertia ixx="2.91666666667e-06" ixy="0.0" ixz="0.0" iyy="2.91666666667e-06" iyz="0.0" izz="2.5e-06"/>
    </inertial>
  </link>
  <!-- Joints -->
  <joint name="anchor" type="fixed">
    <origin rpy="0 0 0" xyz="0 0 0.001"/>
    <parent link="world"/>
    <child link="base_link"/>
  </joint>
  <joint name="SA" type="revolute">
    <child link="manifold"/>
    <parent link="base_link"/>
    <axis xyz="0 0 1"/>
    <origin rpy="0 0 0" xyz="0 0 0.01524"/>
    <limit effort="400" lower="-1.57079632679" upper="1.57079632679" velocity="10"/>
    <!--"${80*pi/180}" /-->
    <dynamics damping="5"/>
  </joint>
  <joint name="SE" type="revolute">
    <child link="upper_arm"/>
    <parent link="manifold"/>
    <axis xyz="1 0 0"/>
    <origin rpy="0 0 0" xyz="0 0 0.33812"/>
    <limit effort="400" lower="-1.57079632679" upper="0.523598775598" velocity="10"/>
    <!--"${65*pi/180}" /-->
    <dynamics damping="5" friction="10"/>
  </joint>
  <joint name="linkage_tr" type="revolute">
    <child link="forearm"/>
    <parent link="upper_arm"/>
    <axis xyz="1 0 0"/>
    <origin rpy="0 0 0" xyz="0 -9.82e-3 0.52167"/>
    <limit effort="400" lower="-0.698131700798" upper="1.2217304764" velocity="10"/>
    <!--"${50*pi/180}" /-->
    <dynamics damping="10"/>
  </joint>
  <joint name="WP" type="revolute">
    <child link="pitch"/>
    <parent link="forearm"/>
    <axis xyz="1 0 0"/>
    <origin rpy="0 0 0" xyz="0 0.26109 7.5e-3"/>
    <limit effort="400" lower="-0.610865238198" upper="1.1344640138" velocity="10"/>
    <!--"${100*pi/180}" /-->
    <dynamics damping="5"/>
  </joint>
  <joint name="WY" type="revolute">
    <child link="yaw"/>
    <parent link="pitch"/>
    <axis xyz="0 0 1"/>
    <origin rpy="0 0 0" xyz="0 0.133223 0"/>
    <limit effort="400" lower="-0.680678408278" upper="1.15191730632" velocity="10"/>
    <!--"${115*pi/180}" /-->
    <dynamics damping="5"/>
  </joint>
  <joint name="WR" type="revolute">
    <child link="end_effector"/>
    <parent link="yaw"/>
    <axis xyz="0 1 0"/>
    <origin rpy="0 0 0" xyz="-0.787e-3 0.190892 0.051331"/>
    <limit effort="400" lower="-1.74532925199" upper="1.74532925199" velocity="10"/>
    <!--"${200*pi/180}" /-->
    <dynamics damping="0.5"/>
  </joint>
  <transmission name="SA_tran" type="transmission_interface/SimpleTransmission">
    <type>transmission_interface/SimpleTransmission</type>
    <joint name="SA">
      <!--hardwareInterface>hardware_interface/EffortJointInterface</hardwareInterface-->
      <hardwareInterface>hardware_interface/PositionJointInterface</hardwareInterface>
    </joint>
    <actuator name="SA_motor">
      <!--hardwareInterface>hardware_interface/EffortJointInterface</hardwareInterface-->
      <hardwareInterface>hardware_interface/PositionJointInterface</hardwareInterface>
      <mechanicalReduction>1</mechanicalReduction>
    </actuator>
    <mechanicalReduction>1</mechanicalReduction>
  </transmission>
  <transmission name="SE_tran" type="transmission_interface/SimpleTransmission">
    <type>transmission_interface/SimpleTransmission</type>
    <joint name="SE">
      <!--hardwareInterface>hardware_interface/EffortJointInterface</hardwareInterface-->
      <hardwareInterface>hardware_interface/PositionJointInterface</hardwareInterface>
    </joint>
    <actuator name="SE_motor">
      <!--hardwareInterface>hardware_interface/EffortJointInterface</hardwareInterface-->
      <hardwareInterface>hardware_interface/PositionJointInterface</hardwareInterface>
      <mechanicalReduction>1</mechanicalReduction>
    </actuator>
    <mechanicalReduction>1</mechanicalReduction>
  </transmission>
  <transmission name="linkage_tr_tran" type="transmission_interface/SimpleTransmission">
    <type>transmission_interface/SimpleTransmission</type>
    <joint name="linkage_tr">
      <!--hardwareInterface>hardware_interface/EffortJointInterface</hardwareInterface-->
      <hardwareInterface>hardware_interface/PositionJointInterface</hardwareInterface>
    </joint>
    <actuator name="linkage_tr_motor">
      <!--hardwareInterface>hardware_interface/EffortJointInterface</hardwareInterface-->
      <hardwareInterface>hardware_interface/PositionJointInterface</hardwareInterface>
      <mechanicalReduction>1</mechanicalReduction>
    </actuator>
    <mechanicalReduction>1</mechanicalReduction>
  </transmission>
  <transmission name="WP_tran" type="transmission_interface/SimpleTransmission">
    <type>transmission_interface/SimpleTransmission</type>
    <joint name="WP">
      <!--hardwareInterface>hardware_interface/EffortJointInterface</hardwareInterface-->
      <hardwareInterface>hardware_interface/PositionJointInterface</hardwareInterface>
    </joint>
    <actuator name="WP_motor">
      <!--hardwareInterface>hardware_interface/EffortJointInterface</hardwareInterface-->
      <hardwareInterface>hardware_interface/PositionJointInterface</hardwareInterface>
      <mechanicalReduction>1</mechanicalReduction>
    </actuator>
    <mechanicalReduction>1</mechanicalReduction>
  </transmission>
  <transmission name="WY_tran" type="transmission_interface/SimpleTransmission">
    <type>transmission_interface/SimpleTransmission</type>
    <joint name="WY">
      <!--hardwareInterface>hardware_interface/EffortJointInterface</hardwareInterface-->
      <hardwareInterface>hardware_interface/PositionJointInterface</hardwareInterface>
    </joint>
    <actuator name="WY_motor">
      <!--hardwareInterface>hardware_interface/EffortJointInterface</hardwareInterface-->
      <hardwareInterface>hardware_interface/PositionJointInterface</hardwareInterface>
      <mechanicalReduction>1</mechanicalReduction>
    </actuator>
    <mechanicalReduction>1</mechanicalReduction>
  </transmission>
  <transmission name="WR_tran" type="transmission_interface/SimpleTransmission">
    <type>transmission_interface/SimpleTransmission</type>
    <joint name="WR">
      <!--hardwareInterface>hardware_interface/EffortJointInterface</hardwareInterface-->
      <hardwareInterface>hardware_interface/PositionJointInterface</hardwareInterface>
    </joint>
    <actuator name="WR_motor">
      <!--hardwareInterface>hardware_interface/EffortJointInterface</hardwareInterface-->
      <hardwareInterface>hardware_interface/PositionJointInterface</hardwareInterface>
      <mechanicalReduction>1</mechanicalReduction>
    </actuator>
    <mechanicalReduction>1</mechanicalReduction>
  </transmission>
  <gazebo reference="base_link">
    <material>Telerobcar/MetalSeamed</material>
    <selfCollide>false</selfCollide>
  </gazebo>
  <gazebo reference="manifold">
    <material>Telerobcar/MetalSeamed</material>
    <selfCollide>false</selfCollide>
  </gazebo>
  <gazebo reference="upper_arm">
    <material>Telerobcar/MetalSeamed</material>
    <selfCollide>false</selfCollide>
  </gazebo>
  <gazebo reference="forearm">
    <material>Telerobcar/MetalSeamed</material>
    <selfCollide>false</selfCollide>
  </gazebo>
  <gazebo reference="pitch">
    <material>Telerobcar/MetalSeamed</material>
    <selfCollide>false</selfCollide>
  </gazebo>
  <gazebo reference="yaw">
    <material>Telerobcar/MetalSeamed</material>
    <selfCollide>false</selfCollide>
  </gazebo>
  <gazebo reference="end_effector">
    <selfCollide>false</selfCollide>
  </gazebo>
  <link name="gripper_base">
    <visual>
      <geometry>
        <mesh filename="package://kraft_description/meshes/visual/gripper_base.dae"/>
      </geometry>
      <material name="metal_seamed"/>
    </visual>
    <inertial>
      <mass value="0.923"/>
      <origin rpy="0 0 0" xyz="0 26.28e-3 0"/>
      <inertia ixx="9.67e-4" ixy="0.0" ixz="0.0" iyy="0.002" iyz="0.0" izz="0.002"/>
    </inertial>
    <collision name="collision">
      <geometry>
        <!--<cylinder radius="0.1" length="0.2" />-->
        <mesh filename="package://kraft_description/meshes/collision/gripper_base.dae"/>
      </geometry>
    </collision>
  </link>
  <link name="r_outer">
    <visual>
      <geometry>
        <mesh filename="package://kraft_description/meshes/visual/outer_pivot.dae"/>
      </geometry>
      <material name="metal_seamed"/>
    </visual>
    <inertial>
      <mass value="0.091"/>
      <origin rpy="0 0 0" xyz="0 31.725e-3 0"/>
      <inertia ixx="4.664e-5" ixy="0.0" ixz="0.0" iyy="5.519e-6" iyz="0.0" izz="4.682e-5"/>
    </inertial>
    <collision name="collision">
      <geometry>
        <!--<cylinder radius="0.1" length="0.2" />-->
        <mesh filename="package://kraft_description/meshes/collision/outer_pivot.dae"/>
      </geometry>
    </collision>
  </link>
  <link name="l_outer">
    <visual>
      <geometry>
        <mesh filename="package://kraft_description/meshes/visual/outer_pivot.dae"/>
      </geometry>
      <material name="metal_seamed"/>
    </visual>
    <inertial>
      <mass value="0.091"/>
      <origin rpy="0 0 0" xyz="0 31.725e-3 0"/>
      <inertia ixx="4.664e-5" ixy="0.0" ixz="0.0" iyy="5.519e-6" iyz="0.0" izz="4.682e-5"/>
    </inertial>
    <collision name="collision">
      <geometry>
        <!--<cylinder radius="0.1" length="0.2" />-->
        <mesh filename="package://kraft_description/meshes/collision/outer_pivot.dae"/>
      </geometry>
    </collision>
  </link>
  <link name="r_inner">
    <visual>
      <geometry>
        <mesh filename="package://kraft_description/meshes/visual/r_inner_pivot.dae"/>
      </geometry>
      <material name="metal_seamed"/>
    </visual>
    <inertial>
      <mass value="0.194"/>
      <origin rpy="0 0 0" xyz="-0.316e-3 23.873e-3 0"/>
      <inertia ixx="1.179e-4" ixy="1.347e-6" ixz="0.0" iyy="5.647e-5" iyz="0.0" izz="7.353e-5"/>
    </inertial>
    <collision name="collision">
      <geometry>
        <!--<cylinder radius="0.1" length="0.2" />-->
        <mesh filename="package://kraft_description/meshes/collision/r_inner_pivot.dae"/>
      </geometry>
    </collision>
  </link>
  <link name="l_inner">
    <visual>
      <geometry>
        <mesh filename="package://kraft_description/meshes/visual/l_inner_pivot.dae"/>
      </geometry>
      <material name="metal_seamed"/>
    </visual>
    <inertial>
      <mass value="0.194"/>
      <origin rpy="0 0 0" xyz="0.316e-3 23.873e-3 0"/>
      <inertia ixx="1.179e-4" ixy="-1.347e-6" ixz="0.0" iyy="5.647e-5" iyz="0.0" izz="7.353e-5"/>
    </inertial>
    <collision name="collision">
      <geometry>
        <!--<cylinder radius="0.1" length="0.2" />-->
        <mesh filename="package://kraft_description/meshes/collision/l_inner_pivot.dae"/>
      </geometry>
    </collision>
  </link>
  <link name="r_finger">
    <visual>
      <geometry>
        <mesh filename="package://kraft_description/meshes/visual/r_finger.dae"/>
      </geometry>
      <material name="metal_seamed"/>
    </visual>
    <inertial>
      <mass value="0.174"/>
      <origin rpy="0 0 0" xyz="3.441e-3 20.353e-3 0"/>
      <inertia ixx="1.65e-4" ixy="3.16e-5" ixz="0.0" iyy="3.595e-5" iyz="0.0" izz="1.701e-4"/>
    </inertial>
    <collision name="collision">
      <geometry>
        <!--<cylinder radius="0.1" length="0.2" />-->
        <mesh filename="package://kraft_description/meshes/collision/r_finger.dae"/>
      </geometry>
    </collision>
  </link>
  <link name="l_finger">
    <visual>
      <geometry>
        <mesh filename="package://kraft_description/meshes/visual/l_finger.dae"/>
      </geometry>
      <material name="metal_seamed"/>
    </visual>
    <inertial>
      <mass value="0.174"/>
      <origin rpy="0 0 0" xyz="-3.441e-3 20.353e-3 0"/>
      <inertia ixx="1.65e-4" ixy="-3.16e-5" ixz="0.0" iyy="3.595e-5" iyz="0.0" izz="1.701e-4"/>
    </inertial>
    <collision name="collision">
      <geometry>
        <!--<cylinder radius="0.1" length="0.2" />-->
        <mesh filename="package://kraft_description/meshes/collision/l_finger.dae"/>
      </geometry>
    </collision>
  </link>
  <!-- joints -->
  <joint name="gripper_base_joint" type="fixed">
    <parent link="end_effector"/>
    <child link="gripper_base"/>
    <origin rpy="0 0 0" xyz="0 0 0"/>
  </joint>
  <joint name="r_inner" type="revolute">
    <child link="r_inner"/>
    <parent link="gripper_base"/>
    <axis xyz="0 0 1"/>
    <origin rpy="0 0 0" xyz="31.737e-3 42.19e-3 0"/>
    <limit effort="200" lower="-1.43" upper="0.4" velocity="15"/>
    <dynamics damping="0"/>
  </joint>
  <joint name="l_inner" type="revolute">
    <child link="l_inner"/>
    <parent link="gripper_base"/>
    <axis xyz="0 0 1"/>
    <origin rpy="0 0 0" xyz="-31.737e-3 42.19e-3 0"/>
    <limit effort="200" lower="-0.4" upper="1.43" velocity="15"/>
    <dynamics damping="0"/>
  </joint>
  <joint name="r_outer" type="revolute">
    <child link="r_outer"/>
    <parent link="gripper_base"/>
    <axis xyz="0 0 1"/>
    <origin rpy="0 0 0" xyz="58.93e-3 26.49e-3 0"/>
    <limit effort="200" lower="-1.43" upper="0.4" velocity="15"/>
    <dynamics damping="0"/>
  </joint>
  <joint name="l_outer" type="revolute">
    <child link="l_outer"/>
    <parent link="gripper_base"/>
    <axis xyz="0 0 1"/>
    <origin rpy="0 0 0" xyz="-58.93e-3 26.49e-3 0"/>
    <limit effort="200" lower="-0.4" upper="1.43" velocity="15"/>
    <dynamics damping="0"/>
  </joint>
  <joint name="r_finger" type="revolute">
    <child link="r_finger"/>
    <parent link="r_inner"/>
    <axis xyz="0 0 1"/>
    <origin rpy="0 0 0" xyz="0 63.45e-3 0"/>
    <limit effort="200" lower="-1.57079632679" upper="1.57079632679" velocity="15"/>
    <dynamics damping="0"/>
  </joint>
  <joint name="l_finger" type="revolute">
    <child link="l_finger"/>
    <parent link="l_inner"/>
    <axis xyz="0 0 1"/>
    <origin rpy="0 0 0" xyz="0 63.45e-3 0"/>
    <limit effort="200" lower="-1.57079632679" upper="1.57079632679" velocity="15"/>
    <dynamics damping="0"/>
  </joint>
  <transmission name="r_outer_tran" type="transmission_interface/SimpleTransmission">
    <type>transmission_interface/SimpleTransmission</type>
    <joint name="r_outer">
      <!--hardwareInterface>hardware_interface/EffortJointInterface</hardwareInterface-->
      <hardwareInterface>hardware_interface/PositionJointInterface</hardwareInterface>
    </joint>
    <actuator name="r_outer_motor">
      <!--hardwareInterface>hardware_interface/EffortJointInterface</hardwareInterface-->
      <hardwareInterface>hardware_interface/PositionJointInterface</hardwareInterface>
      <mechanicalReduction>1</mechanicalReduction>
    </actuator>
    <mechanicalReduction>1</mechanicalReduction>
  </transmission>
  <transmission name="l_outer_tran" type="transmission_interface/SimpleTransmission">
    <type>transmission_interface/SimpleTransmission</type>
    <joint name="l_outer">
      <!--hardwareInterface>hardware_interface/EffortJointInterface</hardwareInterface-->
      <hardwareInterface>hardware_interface/PositionJointInterface</hardwareInterface>
    </joint>
    <actuator name="l_outer_motor">
      <!--hardwareInterface>hardware_interface/EffortJointInterface</hardwareInterface-->
      <hardwareInterface>hardware_interface/PositionJointInterface</hardwareInterface>
      <mechanicalReduction>1</mechanicalReduction>
    </actuator>
    <mechanicalReduction>1</mechanicalReduction>
  </transmission>
  <transmission name="r_inner_tran" type="transmission_interface/SimpleTransmission">
    <type>transmission_interface/SimpleTransmission</type>
    <joint name="r_inner">
      <!--hardwareInterface>hardware_interface/EffortJointInterface</hardwareInterface-->
      <hardwareInterface>hardware_interface/PositionJointInterface</hardwareInterface>
    </joint>
    <actuator name="r_inner_motor">
      <!--hardwareInterface>hardware_interface/EffortJointInterface</hardwareInterface-->
      <hardwareInterface>hardware_interface/PositionJointInterface</hardwareInterface>
      <mechanicalReduction>1</mechanicalReduction>
    </actuator>
    <mechanicalReduction>1</mechanicalReduction>
  </transmission>
  <transmission name="l_inner_tran" type="transmission_interface/SimpleTransmission">
    <type>transmission_interface/SimpleTransmission</type>
    <joint name="l_inner">
      <!--hardwareInterface>hardware_interface/EffortJointInterface</hardwareInterface-->
      <hardwareInterface>hardware_interface/PositionJointInterface</hardwareInterface>
    </joint>
    <actuator name="l_inner_motor">
      <!--hardwareInterface>hardware_interface/EffortJointInterface</hardwareInterface-->
      <hardwareInterface>hardware_interface/PositionJointInterface</hardwareInterface>
      <mechanicalReduction>1</mechanicalReduction>
    </actuator>
    <mechanicalReduction>1</mechanicalReduction>
  </transmission>
  <transmission name="r_finger_tran" type="transmission_interface/SimpleTransmission">
    <type>transmission_interface/SimpleTransmission</type>
    <joint name="r_finger">
      <!--hardwareInterface>hardware_interface/EffortJointInterface</hardwareInterface-->
      <hardwareInterface>hardware_interface/PositionJointInterface</hardwareInterface>
    </joint>
    <actuator name="r_finger_motor">
      <!--hardwareInterface>hardware_interface/EffortJointInterface</hardwareInterface-->
      <hardwareInterface>hardware_interface/PositionJointInterface</hardwareInterface>
      <mechanicalReduction>1</mechanicalReduction>
    </actuator>
    <mechanicalReduction>1</mechanicalReduction>
  </transmission>
  <transmission name="l_finger_tran" type="transmission_interface/SimpleTransmission">
    <type>transmission_interface/SimpleTransmission</type>
    <joint name="l_finger">
      <!--hardwareInterface>hardware_interface/EffortJointInterface</hardwareInterface-->
      <hardwareInterface>hardware_interface/PositionJointInterface</hardwareInterface>
    </joint>
    <actuator name="l_finger_motor">
      <!--hardwareInterface>hardware_interface/EffortJointInterface</hardwareInterface-->
      <hardwareInterface>hardware_interface/PositionJointInterface</hardwareInterface>
      <mechanicalReduction>1</mechanicalReduction>
    </actuator>
    <mechanicalReduction>1</mechanicalReduction>
  </transmission>
  <!-- links -->
  <gazebo reference="gripper_base">
    <material>Telerobcar/MetalSeamed</material>
    <selfCollide>false</selfCollide>
  </gazebo>
  <gazebo reference="r_outer">
    <material>Telerobcar/MetalSeamed</material>
    <selfCollide>false</selfCollide>
  </gazebo>
  <gazebo reference="l_outer">
    <material>Telerobcar/MetalSeamed</material>
    <selfCollide>false</selfCollide>
  </gazebo>
  <gazebo reference="r_inner">
    <material>Telerobcar/MetalSeamed</material>
    <selfCollide>false</selfCollide>
  </gazebo>
  <gazebo reference="l_inner">
    <material>Telerobcar/MetalSeamed</material>
    <selfCollide>false</selfCollide>
  </gazebo>
  <gazebo reference="r_finger">
    <material>Telerobcar/MetalSeamed</material>
    <selfCollide>false</selfCollide>
    <mu1>1.1</mu1>
    <mu2>1.1</mu2>
    <fdir1>0 0 1</fdir1>
    <kp>1000000.0</kp>
    <kd>10.0</kd>
    <maxVel>0.1</maxVel>
    <minDepth>0.001</minDepth>
    <maxContacts>5</maxContacts>
  </gazebo>
  <gazebo reference="l_finger">
    <material>Telerobcar/MetalSeamed</material>
    <selfCollide>false</selfCollide>
    <mu1>1.1</mu1>
    <mu2>1.1</mu2>
    <fdir1>0 0 1</fdir1>
    <kp>1000000.0</kp>
    <kd>100.0</kd>
    <maxVel>0.1</maxVel>
    <minDepth>0.001</minDepth>
    <maxContacts>5</maxContacts>
  </gazebo>
  <gazebo>
    <gripper name="grasping">
      <grasp_check>
        <attach_steps>1</attach_steps>
        <!-- default: 20 -->
        <detach_steps>1</detach_steps>
        <!-- default: 40 -->
        <min_contact_count>2</min_contact_count>
      </grasp_check>
      <gripper_link>r_finger</gripper_link>
      <gripper_link>l_finger</gripper_link>
      <palm_link>gripper_base</palm_link>
    </gripper>
  </gazebo>
  <!-- Add the ft_sensor >
  <ftsensor parent="end_effector"/-->
  <!-- ros_control plugin  -->
  <gazebo>
    <plugin filename="libgazebo_ros_control.so" name="ros_control"/>
  </gazebo>
  <gazebo>
    <plugin filename="libgazebo_ros_joint_state_publisher.so" name="joint_state_publisher">
      <jointName>SA, SE, linkage_tr, WP, WY, WR</jointName>
    </plugin>
  </gazebo>
</robot>
