<?xml version="1.0" ?>
<!-- =================================================================================== -->
<!-- |    This document was autogenerated by xacro from kraft.xacro                    | -->
<!-- |    EDITING THIS FILE BY HAND IS NOT RECOMMENDED                                 | -->
<!-- =================================================================================== -->
<robot name="kraft" xmlns:xacro="http://www.ros.org/wiki/xacro">
  <material name="black">
    <color rgba="0.0 0.0 0.0 1.0"/>
  </material>
  <material name="blue">
    <color rgba="0.0 0.0 0.8 1.0"/>
  </material>
  <material name="green">
    <color rgba="0.0 0.8 0.0 1.0"/>
  </material>
  <material name="grey">
    <color rgba="0.2 0.2 0.2 1.0"/>
  </material>
  <material name="orange">
    <color rgba="1.0 0.423529411765 0.0392156862745 1.0"/>
  </material>
  <material name="brown">
    <color rgba="0.870588235294 0.811764705882 0.764705882353 1.0"/>
  </material>
  <material name="red">
    <color rgba="0.8 0.0 0.0 1.0"/>
  </material>
  <material name="white">
    <color rgba="1.0 1.0 1.0 1.0"/>
  </material>
  <material name="metal_seamed">
    <color rgba="0.4627450980392157 0.4666666666666667 0.4509803921568628 1.0"/>
  </material>
  <!-- Density: 1750 kg/m3 -->
  <!-- Create the grips robot -->
  <link name="world"/>
  <link name="base_link">
    <visual>
      <geometry>
        <mesh filename="package://kraft_description/meshes/visual/base.dae"/>
      </geometry>
      <material name="black"/>
    </visual>
    <collision>
      <origin rpy="0 0 0" xyz="0 0 0.00762"/>
      <geometry>
        <cylinder length="0.01524" radius="0.125"/>
      </geometry>
    </collision>
    <inertial>
      <origin rpy="0 0 0" xyz="0 0 0.00762"/>
      <mass value="1.208"/>
      <inertia ixx="0.0047421305984" ixy="0.0" ixz="0.0" iyy="0.0047421305984" iyz="0.0" izz="0.0094375"/>
    </inertial>
  </link>
  <link name="manifold">
    <visual>
      <geometry>
        <mesh filename="package://kraft_description/meshes/visual/manifold.dae"/>
      </geometry>
      <material name="black"/>
    </visual>
    <collision>
      <origin rpy="0 0 0" xyz="0 0 0.16906"/>
      <geometry>
        <cylinder length="0.33812" radius="0.205"/>
      </geometry>
    </collision>
    <inertial>
      <origin rpy="0 0 0" xyz="0 0 0.16906"/>
      <mass value="41.111"/>
      <inertia ixx="0.82359082711" ixy="0.0" ixz="0.0" iyy="0.82359082711" iyz="0.0" izz="0.8638448875"/>
    </inertial>
  </link>
  <link name="upper_arm">
    <visual>
      <geometry>
        <mesh filename="package://kraft_description/meshes/visual/upper_arm.dae"/>
      </geometry>
      <material name="black"/>
    </visual>
    <collision>
      <origin rpy="0 0 0" xyz="0 0 0.260835"/>
      <geometry>
        <cylinder length="0.52167" radius="0.075"/>
      </geometry>
    </collision>
    <inertial>
      <origin rpy="0 0 0" xyz="0 0 0.260835"/>
      <mass value="3.592"/>
      <inertia ixx="0.0865117002774" ixy="0.0" ixz="0.0" iyy="0.0865117002774" iyz="0.0" izz="0.0101025"/>
    </inertial>
  </link>
  <link name="forearm">
    <visual>
      <geometry>
        <mesh filename="package://kraft_description/meshes/visual/forearm.dae"/>
      </geometry>
      <material name="black"/>
    </visual>
    <collision>
      <origin rpy="1.57079632679 0 0" xyz="0 0.069139 0"/>
      <geometry>
        <cylinder length="0.385078" radius="0.075"/>
      </geometry>
    </collision>
    <inertial>
      <origin rpy="0 0 0" xyz="0 0.069139 0"/>
      <mass value="4.935"/>
      <inertia ixx="0.067922077177" ixy="0.0" ixz="0.0" iyy="0.0138796875" iyz="0.0" izz="0.067922077177"/>
    </inertial>
  </link>
  <link name="pitch">
    <visual>
      <geometry>
        <mesh filename="package://kraft_description/meshes/visual/pitch.dae"/>
      </geometry>
      <material name="black"/>
    </visual>
    <collision>
      <origin rpy="1.57079632679 0 0" xyz="0 0.0666115 0"/>
      <geometry>
        <cylinder length="0.133223" radius="0.075"/>
      </geometry>
    </collision>
    <inertial>
      <origin rpy="0 0 0" xyz="0 0.0666115 0"/>
      <mass value="0.679"/>
      <inertia ixx="0.00195910555733" ixy="0.0" ixz="0.0" iyy="0.0019096875" iyz="0.0" izz="0.00195910555733"/>
    </inertial>
  </link>
  <link name="yaw">
    <visual>
      <geometry>
        <mesh filename="package://kraft_description/meshes/visual/yaw.dae"/>
      </geometry>
      <material name="black"/>
    </visual>
    <collision>
      <origin rpy="1.57079632679 0 0" xyz="0 0.095446 0"/>
      <geometry>
        <cylinder length="0.190892" radius="0.085"/>
      </geometry>
    </collision>
    <inertial>
      <origin rpy="0 0 0" xyz="0 0.095446 0"/>
      <mass value="4.689"/>
      <inertia ixx="0.0227083407757" ixy="0.0" ixz="0.0" iyy="0.0169390125" iyz="0.0" izz="0.0227083407757"/>
    </inertial>
  </link>
  <link name="end_effector">
    <visual>
      <geometry>
        <sphere radius="0.01"/>
      </geometry>
      <material name="blue"/>
    </visual>
    <collision>
      <geometry>
        <sphere radius="0.01"/>
      </geometry>
    </collision>
    <inertial>
      <origin rpy="0 0 0" xyz="0 0 0.01"/>
      <mass value="0.05"/>
      <inertia ixx="2.91666666667e-06" ixy="0.0" ixz="0.0" iyy="2.91666666667e-06" iyz="0.0" izz="2.5e-06"/>
    </inertial>
  </link>
  <!-- Joints -->
  <joint name="anchor" type="fixed">
    <origin rpy="0 0 0" xyz="0 0 0.001"/>
    <parent link="world"/>
    <child link="base_link"/>
  </joint>
  <joint name="SA" type="revolute">
    <child link="manifold"/>
    <parent link="base_link"/>
    <axis xyz="0 0 1"/>
    <origin rpy="0 0 0" xyz="0 0 0.01524"/>
    <limit effort="400" lower="-1.57079632679" upper="1.57079632679" velocity="10"/><!--"1.3962634016"/-->
    <dynamics damping="5"/>
  </joint>
  <joint name="SE" type="revolute">
    <child link="upper_arm"/>
    <parent link="manifold"/>
    <axis xyz="1 0 0"/>
    <origin rpy="0 0 0" xyz="0 0 0.33812"/>
    <limit effort="400" lower="-1.57079632679" upper="0.523598775598" velocity="10"/><!--"1.1344640138"/-->
    <dynamics damping="5" friction="10"/>
  </joint>
  <joint name="linkage_tr" type="revolute">
    <child link="forearm"/>
    <parent link="upper_arm"/>
    <axis xyz="1 0 0"/>
    <origin rpy="0 0 0" xyz="0 -9.82e-3 0.52167"/>
    <limit effort="400" lower="-0.698131700798" upper="1.2217304764" velocity="10"/><!--"0.872664625997"/-->
    <dynamics damping="10"/>
  </joint>
  <joint name="WP" type="revolute">
    <child link="pitch"/>
    <parent link="forearm"/>
    <axis xyz="1 0 0"/>
    <origin rpy="0 0 0" xyz="0 0.26109 7.5e-3"/>
    <limit effort="400" lower="-0.610865238198" upper="1.1344640138" velocity="10"/><!--"1.74532925199"/-->
    <dynamics damping="5"/>
  </joint>
  <joint name="WY" type="revolute">
    <child link="yaw"/>
    <parent link="pitch"/>
    <axis xyz="0 0 1"/>
    <origin rpy="0 0 0" xyz="0 0.133223 0"/>
    <limit effort="400" lower="-0.680678408278" upper="1.15191730632" velocity="10"/><!--"2.00712863979"/-->
    <dynamics damping="5"/>
  </joint>
  <joint name="WR" type="revolute">
    <child link="end_effector"/>
    <parent link="yaw"/>
    <axis xyz="0 1 0"/>
    <origin rpy="0 0 0" xyz="-0.787e-3 0.190892 0.051331"/>
    <limit effort="400" lower="-0.0349065850399" upper="0.0349065850399" velocity="10"/><!--"3.49065850399"/-->
    <dynamics damping="0.5"/>
  </joint>
  <transmission name="SA_tran" type="transmission_interface/SimpleTransmission">
    <type>transmission_interface/SimpleTransmission</type>
    <joint name="SA">
      <!--hardwareInterface>hardware_interface/EffortJointInterface</hardwareInterface-->
      <hardwareInterface>hardware_interface/PositionJointInterface</hardwareInterface>
    </joint>
    <actuator name="SA_motor">
      <!--hardwareInterface>hardware_interface/EffortJointInterface</hardwareInterface-->
      <hardwareInterface>hardware_interface/PositionJointInterface</hardwareInterface>
      <mechanicalReduction>1</mechanicalReduction>
    </actuator>
    <mechanicalReduction>1</mechanicalReduction>
  </transmission>
  <transmission name="SE_tran" type="transmission_interface/SimpleTransmission">
    <type>transmission_interface/SimpleTransmission</type>
    <joint name="SE">
      <!--hardwareInterface>hardware_interface/EffortJointInterface</hardwareInterface-->
      <hardwareInterface>hardware_interface/PositionJointInterface</hardwareInterface>
    </joint>
    <actuator name="SE_motor">
      <!--hardwareInterface>hardware_interface/EffortJointInterface</hardwareInterface-->
      <hardwareInterface>hardware_interface/PositionJointInterface</hardwareInterface>
      <mechanicalReduction>1</mechanicalReduction>
    </actuator>
    <mechanicalReduction>1</mechanicalReduction>
  </transmission>
  <transmission name="linkage_tr_tran" type="transmission_interface/SimpleTransmission">
    <type>transmission_interface/SimpleTransmission</type>
    <joint name="linkage_tr">
      <!--hardwareInterface>hardware_interface/EffortJointInterface</hardwareInterface-->
      <hardwareInterface>hardware_interface/PositionJointInterface</hardwareInterface>
    </joint>
    <actuator name="linkage_tr_motor">
      <!--hardwareInterface>hardware_interface/EffortJointInterface</hardwareInterface-->
      <hardwareInterface>hardware_interface/PositionJointInterface</hardwareInterface>
      <mechanicalReduction>1</mechanicalReduction>
    </actuator>
    <mechanicalReduction>1</mechanicalReduction>
  </transmission>
  <transmission name="WP_tran" type="transmission_interface/SimpleTransmission">
    <type>transmission_interface/SimpleTransmission</type>
    <joint name="WP">
      <!--hardwareInterface>hardware_interface/EffortJointInterface</hardwareInterface-->
      <hardwareInterface>hardware_interface/PositionJointInterface</hardwareInterface>
    </joint>
    <actuator name="WP_motor">
      <!--hardwareInterface>hardware_interface/EffortJointInterface</hardwareInterface-->
      <hardwareInterface>hardware_interface/PositionJointInterface</hardwareInterface>
      <mechanicalReduction>1</mechanicalReduction>
    </actuator>
    <mechanicalReduction>1</mechanicalReduction>
  </transmission>
  <transmission name="WY_tran" type="transmission_interface/SimpleTransmission">
    <type>transmission_interface/SimpleTransmission</type>
    <joint name="WY">
      <!--hardwareInterface>hardware_interface/EffortJointInterface</hardwareInterface-->
      <hardwareInterface>hardware_interface/PositionJointInterface</hardwareInterface>
    </joint>
    <actuator name="WY_motor">
      <!--hardwareInterface>hardware_interface/EffortJointInterface</hardwareInterface-->
      <hardwareInterface>hardware_interface/PositionJointInterface</hardwareInterface>
      <mechanicalReduction>1</mechanicalReduction>
    </actuator>
    <mechanicalReduction>1</mechanicalReduction>
  </transmission>
  <transmission name="WR_tran" type="transmission_interface/SimpleTransmission">
    <type>transmission_interface/SimpleTransmission</type>
    <joint name="WR">
      <!--hardwareInterface>hardware_interface/EffortJointInterface</hardwareInterface-->
      <hardwareInterface>hardware_interface/PositionJointInterface</hardwareInterface>
    </joint>
    <actuator name="WR_motor">
      <!--hardwareInterface>hardware_interface/EffortJointInterface</hardwareInterface-->
      <hardwareInterface>hardware_interface/PositionJointInterface</hardwareInterface>
      <mechanicalReduction>1</mechanicalReduction>
    </actuator>
    <mechanicalReduction>1</mechanicalReduction>
  </transmission>
  <gazebo reference="base_link">
    <material>Telerobcar/MetalSeamed</material>
    <selfCollide>false</selfCollide>
  </gazebo>
  <gazebo reference="manifold">
    <material>Telerobcar/MetalSeamed</material>
    <selfCollide>false</selfCollide>
  </gazebo>
  <gazebo reference="upper_arm">
    <material>Telerobcar/MetalSeamed</material>
    <selfCollide>false</selfCollide>
  </gazebo>
  <gazebo reference="forearm">
    <material>Telerobcar/MetalSeamed</material>
    <selfCollide>false</selfCollide>
  </gazebo>
  <gazebo reference="pitch">
    <material>Telerobcar/MetalSeamed</material>
    <selfCollide>false</selfCollide>
  </gazebo>
  <gazebo reference="yaw">
    <material>Telerobcar/MetalSeamed</material>
    <selfCollide>false</selfCollide>
  </gazebo>
  <gazebo reference="end_effector">
    <selfCollide>false</selfCollide>
  </gazebo>
  <link name="wrist_coupling">
    <visual>
      <geometry>
        <mesh filename="package://kraft_description/meshes/visual/wrist_coupling.dae"/>
      </geometry>
      <material name="white"/>
    </visual>
    <collision>
      <origin rpy="0 0 0" xyz="0 0 0.0095"/>
      <geometry>
        <cylinder length="0.019" radius="0.0238"/>
      </geometry>
    </collision>
    <inertial>
      <origin rpy="0 0 0" xyz="0 0 0.0095"/>
      <mass value="0.059"/>
      <inertia ixx="1.01299066667e-05" ixy="0.0" ixz="0.0" iyy="1.01299066667e-05" iyz="0.0" izz="1.670998e-05"/>
    </inertial>
  </link>
  <link name="ft_coupling">
    <visual>
      <geometry>
        <mesh filename="package://kraft_description/meshes/visual/ft_coupling.dae"/>
      </geometry>
      <material name="white"/>
    </visual>
    <!-- Align the collision with the mess. It has an offset of 4.7 mm -->
    <collision>
      <origin rpy="0 0 0" xyz="0 0 0.0142"/>
      <geometry>
        <cylinder length="0.019" radius="0.0337"/>
      </geometry>
    </collision>
    <inertial>
      <origin rpy="0 0 0" xyz="0 0 0.0142"/>
      <mass value="0.1478"/>
      <inertia ixx="4.64100621667e-05" ixy="0.0" ixz="0.0" iyy="4.64100621667e-05" iyz="0.0" izz="8.3927491e-05"/>
    </inertial>
  </link>
  <link name="ft_sensor">
    <visual>
      <origin rpy="-1.57079632679 0 0" xyz="0 0 0"/>
      <geometry>
        <mesh filename="package://kraft_description/meshes/visual/ft_sensor.dae"/>
      </geometry>
      <material name="white"/>
    </visual>
    <collision>
      <origin rpy="0 0 0" xyz="0 0 -0.014"/>
      <geometry>
        <cylinder length="0.028" radius="0.037"/>
      </geometry>
    </collision>
    <inertial>
      <origin rpy="0 0 0" xyz="0 0 -0.014"/>
      <mass value="0.2396"/>
      <inertia ixx="9.76569666667e-05" ixy="0.0" ixz="0.0" iyy="9.76569666667e-05" iyz="0.0" izz="0.0001640062"/>
    </inertial>
  </link>
  <!-- Joints -->
  <joint name="ft_robot_joint" type="fixed">
    <origin rpy="-1.57079632679 0 0" xyz="0 0 0"/>
    <parent link="end_effector"/>
    <child link="wrist_coupling"/>
  </joint>
  <joint name="ft_wrist_joint" type="fixed">
    <origin rpy="0 0 0" xyz="0 0 0"/>
    <parent link="wrist_coupling"/>
    <child link="ft_coupling"/>
  </joint>
  <joint name="ft_sensor_joint" type="fixed">
    <origin rpy="0 0 0" xyz="0 0 0.0517"/>
    <parent link="ft_coupling"/>
    <child link="ft_sensor"/>
  </joint>
  <!-- ros_control plugin  -->
  <gazebo>
    <plugin filename="libgazebo_ros_control.so" name="ros_control"/>
  </gazebo>
  <gazebo>
    <plugin filename="libgazebo_ros_joint_state_publisher.so" name="joint_state_publisher">
      <jointName>SA, SE, linkage_tr, WP, WY, WR</jointName>
    </plugin>
  </gazebo>
</robot>
